2023-05-11 08:38 ERROR Traceback (most recent call last):
  File "c:\Users\user\Desktop\程式專區\TradingSysteam\Crypto_trading\Database\SQL_operate.py", line 31, in get_db_data
    self.userconn = router.Router().mysql_financialdata_conn
  File "c:\Users\user\Desktop\程式專區\TradingSysteam\Crypto_trading\Database\router.py", line 44, in __init__
    self._mysql_financialdata_conn =clients.get_mysql_financialdata_conn()
  File "c:\Users\user\Desktop\程式專區\TradingSysteam\Crypto_trading\Database\clients.py", line 19, in get_mysql_financialdata_conn
    connect = engine.connect()
  File "C:\Users\user\Desktop\程式專區\TradingSysteam\lib\site-packages\sqlalchemy\engine\base.py", line 3315, in connect
    return self._connection_cls(self, close_with_result=close_with_result)
  File "C:\Users\user\Desktop\程式專區\TradingSysteam\lib\site-packages\sqlalchemy\engine\base.py", line 96, in __init__
    else engine.raw_connection()
  File "C:\Users\user\Desktop\程式專區\TradingSysteam\lib\site-packages\sqlalchemy\engine\base.py", line 3394, in raw_connection
    return self._wrap_pool_connect(self.pool.connect, _connection)
  File "C:\Users\user\Desktop\程式專區\TradingSysteam\lib\site-packages\sqlalchemy\engine\base.py", line 3361, in _wrap_pool_connect
    return fn()
  File "C:\Users\user\Desktop\程式專區\TradingSysteam\lib\site-packages\sqlalchemy\pool\base.py", line 325, in connect
    return _ConnectionFairy._checkout(self)
  File "C:\Users\user\Desktop\程式專區\TradingSysteam\lib\site-packages\sqlalchemy\pool\base.py", line 888, in _checkout
    fairy = _ConnectionRecord.checkout(pool)
  File "C:\Users\user\Desktop\程式專區\TradingSysteam\lib\site-packages\sqlalchemy\pool\base.py", line 491, in checkout
    rec = pool._do_get()
  File "C:\Users\user\Desktop\程式專區\TradingSysteam\lib\site-packages\sqlalchemy\pool\impl.py", line 146, in _do_get
    self._dec_overflow()
  File "C:\Users\user\Desktop\程式專區\TradingSysteam\lib\site-packages\sqlalchemy\util\langhelpers.py", line 70, in __exit__
    compat.raise_(
  File "C:\Users\user\Desktop\程式專區\TradingSysteam\lib\site-packages\sqlalchemy\util\compat.py", line 210, in raise_
    raise exception
  File "C:\Users\user\Desktop\程式專區\TradingSysteam\lib\site-packages\sqlalchemy\pool\impl.py", line 143, in _do_get
    return self._create_connection()
  File "C:\Users\user\Desktop\程式專區\TradingSysteam\lib\site-packages\sqlalchemy\pool\base.py", line 271, in _create_connection
    return _ConnectionRecord(self)
  File "C:\Users\user\Desktop\程式專區\TradingSysteam\lib\site-packages\sqlalchemy\pool\base.py", line 386, in __init__
    self.__connect()
  File "C:\Users\user\Desktop\程式專區\TradingSysteam\lib\site-packages\sqlalchemy\pool\base.py", line 685, in __connect
    pool.logger.debug("Error on connect(): %s", e)
  File "C:\Users\user\Desktop\程式專區\TradingSysteam\lib\site-packages\sqlalchemy\util\langhelpers.py", line 70, in __exit__
    compat.raise_(
  File "C:\Users\user\Desktop\程式專區\TradingSysteam\lib\site-packages\sqlalchemy\util\compat.py", line 210, in raise_
    raise exception
  File "C:\Users\user\Desktop\程式專區\TradingSysteam\lib\site-packages\sqlalchemy\pool\base.py", line 680, in __connect
    self.dbapi_connection = connection = pool._invoke_creator(self)
  File "C:\Users\user\Desktop\程式專區\TradingSysteam\lib\site-packages\sqlalchemy\engine\create.py", line 578, in connect
    return dialect.connect(*cargs, **cparams)
  File "C:\Users\user\Desktop\程式專區\TradingSysteam\lib\site-packages\sqlalchemy\engine\default.py", line 598, in connect
    return self.dbapi.connect(*cargs, **cparams)
  File "C:\Users\user\Desktop\程式專區\TradingSysteam\lib\site-packages\pymysql\connections.py", line 352, in __init__
    self.connect()
  File "C:\Users\user\Desktop\程式專區\TradingSysteam\lib\site-packages\pymysql\connections.py", line 636, in connect
    self._request_authentication()
  File "C:\Users\user\Desktop\程式專區\TradingSysteam\lib\site-packages\pymysql\connections.py", line 933, in _request_authentication
    auth_packet = _auth.caching_sha2_password_auth(self, auth_packet)
  File "C:\Users\user\Desktop\程式專區\TradingSysteam\lib\site-packages\pymysql\_auth.py", line 265, in caching_sha2_password_auth
    data = sha2_rsa_encrypt(conn.password, conn.salt, conn.server_public_key)
  File "C:\Users\user\Desktop\程式專區\TradingSysteam\lib\site-packages\pymysql\_auth.py", line 143, in sha2_rsa_encrypt
    raise RuntimeError(
RuntimeError: 'cryptography' package is required for sha256_password or caching_sha2_password auth methods

2023-05-11 08:45 ERROR Traceback (most recent call last):
  File "C:\Users\user\Desktop\程式專區\TradingSysteam\Crypto_trading\Trading_Systeam.py", line 322, in main
    self.check_binance_client_num()
  File "C:\Users\user\Desktop\程式專區\TradingSysteam\Crypto_trading\Trading_Systeam.py", line 277, in check_binance_client_num
    print(len(BinanceSocketManager._clients))
AttributeError: type object 'BinanceSocketManager' has no attribute '_clients'

2023-05-11 13:14 ERROR Traceback (most recent call last):
  File "C:\Users\user\Desktop\程式專區\TradingSysteam\Crypto_trading\Trading_Systeam.py", line 324, in main
    self.check_binance_client_num()
  File "C:\Users\user\Desktop\程式專區\TradingSysteam\Crypto_trading\Trading_Systeam.py", line 279, in check_binance_client_num
    print(len(BinanceSocketManager._clients))
AttributeError: type object 'BinanceSocketManager' has no attribute '_clients'

