2023-10-29 12:56 ERROR Traceback (most recent call last):
  File "C:\Users\user\Desktop\程式專區\TradingSysteam\lib\site-packages\sqlalchemy\engine\base.py", line 1900, in _execute_context
    self.dialect.do_execute(
  File "C:\Users\user\Desktop\程式專區\TradingSysteam\lib\site-packages\sqlalchemy\engine\default.py", line 736, in do_execute
    cursor.execute(statement, parameters)
  File "C:\Users\user\Desktop\程式專區\TradingSysteam\lib\site-packages\pymysql\cursors.py", line 158, in execute
    result = self._query(query)
  File "C:\Users\user\Desktop\程式專區\TradingSysteam\lib\site-packages\pymysql\cursors.py", line 325, in _query
    conn.query(q)
  File "C:\Users\user\Desktop\程式專區\TradingSysteam\lib\site-packages\pymysql\connections.py", line 549, in query
    self._affected_rows = self._read_query_result(unbuffered=unbuffered)
  File "C:\Users\user\Desktop\程式專區\TradingSysteam\lib\site-packages\pymysql\connections.py", line 779, in _read_query_result
    result.read()
  File "C:\Users\user\Desktop\程式專區\TradingSysteam\lib\site-packages\pymysql\connections.py", line 1157, in read
    first_packet = self.connection._read_packet()
  File "C:\Users\user\Desktop\程式專區\TradingSysteam\lib\site-packages\pymysql\connections.py", line 729, in _read_packet
    packet.raise_for_error()
  File "C:\Users\user\Desktop\程式專區\TradingSysteam\lib\site-packages\pymysql\protocol.py", line 221, in raise_for_error
    err.raise_mysql_exception(self._data)
  File "C:\Users\user\Desktop\程式專區\TradingSysteam\lib\site-packages\pymysql\err.py", line 143, in raise_mysql_exception
    raise errorclass(errno, errval)
pymysql.err.OperationalError: (1051, "Unknown table 'crypto_data.{table}'")

The above exception was the direct cause of the following exception:

Traceback (most recent call last):
  File "C:\Users\user\Desktop\程式專區\TradingSysteam\Crypto_trading\Database\SQL_operate.py", line 54, in change_db_data
    conn.execute(text(text_msg))
  File "C:\Users\user\Desktop\程式專區\TradingSysteam\lib\site-packages\sqlalchemy\engine\base.py", line 1380, in execute
    return meth(self, multiparams, params, _EMPTY_EXECUTION_OPTS)
  File "C:\Users\user\Desktop\程式專區\TradingSysteam\lib\site-packages\sqlalchemy\sql\elements.py", line 334, in _execute_on_connection
    return connection._execute_clauseelement(
  File "C:\Users\user\Desktop\程式專區\TradingSysteam\lib\site-packages\sqlalchemy\engine\base.py", line 1572, in _execute_clauseelement
    ret = self._execute_context(
  File "C:\Users\user\Desktop\程式專區\TradingSysteam\lib\site-packages\sqlalchemy\engine\base.py", line 1943, in _execute_context
    self._handle_dbapi_exception(
  File "C:\Users\user\Desktop\程式專區\TradingSysteam\lib\site-packages\sqlalchemy\engine\base.py", line 2124, in _handle_dbapi_exception
    util.raise_(
  File "C:\Users\user\Desktop\程式專區\TradingSysteam\lib\site-packages\sqlalchemy\util\compat.py", line 210, in raise_
    raise exception
  File "C:\Users\user\Desktop\程式專區\TradingSysteam\lib\site-packages\sqlalchemy\engine\base.py", line 1900, in _execute_context
    self.dialect.do_execute(
  File "C:\Users\user\Desktop\程式專區\TradingSysteam\lib\site-packages\sqlalchemy\engine\default.py", line 736, in do_execute
    cursor.execute(statement, parameters)
  File "C:\Users\user\Desktop\程式專區\TradingSysteam\lib\site-packages\pymysql\cursors.py", line 158, in execute
    result = self._query(query)
  File "C:\Users\user\Desktop\程式專區\TradingSysteam\lib\site-packages\pymysql\cursors.py", line 325, in _query
    conn.query(q)
  File "C:\Users\user\Desktop\程式專區\TradingSysteam\lib\site-packages\pymysql\connections.py", line 549, in query
    self._affected_rows = self._read_query_result(unbuffered=unbuffered)
  File "C:\Users\user\Desktop\程式專區\TradingSysteam\lib\site-packages\pymysql\connections.py", line 779, in _read_query_result
    result.read()
  File "C:\Users\user\Desktop\程式專區\TradingSysteam\lib\site-packages\pymysql\connections.py", line 1157, in read
    first_packet = self.connection._read_packet()
  File "C:\Users\user\Desktop\程式專區\TradingSysteam\lib\site-packages\pymysql\connections.py", line 729, in _read_packet
    packet.raise_for_error()
  File "C:\Users\user\Desktop\程式專區\TradingSysteam\lib\site-packages\pymysql\protocol.py", line 221, in raise_for_error
    err.raise_mysql_exception(self._data)
  File "C:\Users\user\Desktop\程式專區\TradingSysteam\lib\site-packages\pymysql\err.py", line 143, in raise_mysql_exception
    raise errorclass(errno, errval)
sqlalchemy.exc.OperationalError: (pymysql.err.OperationalError) (1051, "Unknown table 'crypto_data.{table}'")
[SQL: drop table `{table}`]
(Background on this error at: https://sqlalche.me/e/14/e3q8)

2023-10-29 12:56 ERROR Traceback (most recent call last):
  File "C:\Users\user\Desktop\程式專區\TradingSysteam\lib\site-packages\sqlalchemy\engine\base.py", line 1900, in _execute_context
    self.dialect.do_execute(
  File "C:\Users\user\Desktop\程式專區\TradingSysteam\lib\site-packages\sqlalchemy\engine\default.py", line 736, in do_execute
    cursor.execute(statement, parameters)
  File "C:\Users\user\Desktop\程式專區\TradingSysteam\lib\site-packages\pymysql\cursors.py", line 158, in execute
    result = self._query(query)
  File "C:\Users\user\Desktop\程式專區\TradingSysteam\lib\site-packages\pymysql\cursors.py", line 325, in _query
    conn.query(q)
  File "C:\Users\user\Desktop\程式專區\TradingSysteam\lib\site-packages\pymysql\connections.py", line 549, in query
    self._affected_rows = self._read_query_result(unbuffered=unbuffered)
  File "C:\Users\user\Desktop\程式專區\TradingSysteam\lib\site-packages\pymysql\connections.py", line 779, in _read_query_result
    result.read()
  File "C:\Users\user\Desktop\程式專區\TradingSysteam\lib\site-packages\pymysql\connections.py", line 1157, in read
    first_packet = self.connection._read_packet()
  File "C:\Users\user\Desktop\程式專區\TradingSysteam\lib\site-packages\pymysql\connections.py", line 729, in _read_packet
    packet.raise_for_error()
  File "C:\Users\user\Desktop\程式專區\TradingSysteam\lib\site-packages\pymysql\protocol.py", line 221, in raise_for_error
    err.raise_mysql_exception(self._data)
  File "C:\Users\user\Desktop\程式專區\TradingSysteam\lib\site-packages\pymysql\err.py", line 143, in raise_mysql_exception
    raise errorclass(errno, errval)
pymysql.err.OperationalError: (3730, "Cannot drop table 'auth_group' referenced by a foreign key constraint 'auth_group_permissions_group_id_b120cbf9_fk_auth_group_id' on table 'auth_group_permissions'.")

The above exception was the direct cause of the following exception:

Traceback (most recent call last):
  File "C:\Users\user\Desktop\程式專區\TradingSysteam\Crypto_trading\Database\SQL_operate.py", line 54, in change_db_data
    conn.execute(text(text_msg))
  File "C:\Users\user\Desktop\程式專區\TradingSysteam\lib\site-packages\sqlalchemy\engine\base.py", line 1380, in execute
    return meth(self, multiparams, params, _EMPTY_EXECUTION_OPTS)
  File "C:\Users\user\Desktop\程式專區\TradingSysteam\lib\site-packages\sqlalchemy\sql\elements.py", line 334, in _execute_on_connection
    return connection._execute_clauseelement(
  File "C:\Users\user\Desktop\程式專區\TradingSysteam\lib\site-packages\sqlalchemy\engine\base.py", line 1572, in _execute_clauseelement
    ret = self._execute_context(
  File "C:\Users\user\Desktop\程式專區\TradingSysteam\lib\site-packages\sqlalchemy\engine\base.py", line 1943, in _execute_context
    self._handle_dbapi_exception(
  File "C:\Users\user\Desktop\程式專區\TradingSysteam\lib\site-packages\sqlalchemy\engine\base.py", line 2124, in _handle_dbapi_exception
    util.raise_(
  File "C:\Users\user\Desktop\程式專區\TradingSysteam\lib\site-packages\sqlalchemy\util\compat.py", line 210, in raise_
    raise exception
  File "C:\Users\user\Desktop\程式專區\TradingSysteam\lib\site-packages\sqlalchemy\engine\base.py", line 1900, in _execute_context
    self.dialect.do_execute(
  File "C:\Users\user\Desktop\程式專區\TradingSysteam\lib\site-packages\sqlalchemy\engine\default.py", line 736, in do_execute
    cursor.execute(statement, parameters)
  File "C:\Users\user\Desktop\程式專區\TradingSysteam\lib\site-packages\pymysql\cursors.py", line 158, in execute
    result = self._query(query)
  File "C:\Users\user\Desktop\程式專區\TradingSysteam\lib\site-packages\pymysql\cursors.py", line 325, in _query
    conn.query(q)
  File "C:\Users\user\Desktop\程式專區\TradingSysteam\lib\site-packages\pymysql\connections.py", line 549, in query
    self._affected_rows = self._read_query_result(unbuffered=unbuffered)
  File "C:\Users\user\Desktop\程式專區\TradingSysteam\lib\site-packages\pymysql\connections.py", line 779, in _read_query_result
    result.read()
  File "C:\Users\user\Desktop\程式專區\TradingSysteam\lib\site-packages\pymysql\connections.py", line 1157, in read
    first_packet = self.connection._read_packet()
  File "C:\Users\user\Desktop\程式專區\TradingSysteam\lib\site-packages\pymysql\connections.py", line 729, in _read_packet
    packet.raise_for_error()
  File "C:\Users\user\Desktop\程式專區\TradingSysteam\lib\site-packages\pymysql\protocol.py", line 221, in raise_for_error
    err.raise_mysql_exception(self._data)
  File "C:\Users\user\Desktop\程式專區\TradingSysteam\lib\site-packages\pymysql\err.py", line 143, in raise_mysql_exception
    raise errorclass(errno, errval)
sqlalchemy.exc.OperationalError: (pymysql.err.OperationalError) (3730, "Cannot drop table 'auth_group' referenced by a foreign key constraint 'auth_group_permissions_group_id_b120cbf9_fk_auth_group_id' on table 'auth_group_permissions'.")
[SQL: drop table `auth_group`]
(Background on this error at: https://sqlalche.me/e/14/e3q8)

2023-10-29 12:57 ERROR Traceback (most recent call last):
  File "C:\Users\user\Desktop\程式專區\TradingSysteam\lib\site-packages\sqlalchemy\engine\base.py", line 1900, in _execute_context
    self.dialect.do_execute(
  File "C:\Users\user\Desktop\程式專區\TradingSysteam\lib\site-packages\sqlalchemy\engine\default.py", line 736, in do_execute
    cursor.execute(statement, parameters)
  File "C:\Users\user\Desktop\程式專區\TradingSysteam\lib\site-packages\pymysql\cursors.py", line 158, in execute
    result = self._query(query)
  File "C:\Users\user\Desktop\程式專區\TradingSysteam\lib\site-packages\pymysql\cursors.py", line 325, in _query
    conn.query(q)
  File "C:\Users\user\Desktop\程式專區\TradingSysteam\lib\site-packages\pymysql\connections.py", line 549, in query
    self._affected_rows = self._read_query_result(unbuffered=unbuffered)
  File "C:\Users\user\Desktop\程式專區\TradingSysteam\lib\site-packages\pymysql\connections.py", line 779, in _read_query_result
    result.read()
  File "C:\Users\user\Desktop\程式專區\TradingSysteam\lib\site-packages\pymysql\connections.py", line 1157, in read
    first_packet = self.connection._read_packet()
  File "C:\Users\user\Desktop\程式專區\TradingSysteam\lib\site-packages\pymysql\connections.py", line 729, in _read_packet
    packet.raise_for_error()
  File "C:\Users\user\Desktop\程式專區\TradingSysteam\lib\site-packages\pymysql\protocol.py", line 221, in raise_for_error
    err.raise_mysql_exception(self._data)
  File "C:\Users\user\Desktop\程式專區\TradingSysteam\lib\site-packages\pymysql\err.py", line 143, in raise_mysql_exception
    raise errorclass(errno, errval)
pymysql.err.OperationalError: (3730, "Cannot drop table 'auth_group' referenced by a foreign key constraint 'auth_user_groups_group_id_97559544_fk_auth_group_id' on table 'auth_user_groups'.")

The above exception was the direct cause of the following exception:

Traceback (most recent call last):
  File "C:\Users\user\Desktop\程式專區\TradingSysteam\Crypto_trading\Database\SQL_operate.py", line 54, in change_db_data
    conn.execute(text(text_msg))
  File "C:\Users\user\Desktop\程式專區\TradingSysteam\lib\site-packages\sqlalchemy\engine\base.py", line 1380, in execute
    return meth(self, multiparams, params, _EMPTY_EXECUTION_OPTS)
  File "C:\Users\user\Desktop\程式專區\TradingSysteam\lib\site-packages\sqlalchemy\sql\elements.py", line 334, in _execute_on_connection
    return connection._execute_clauseelement(
  File "C:\Users\user\Desktop\程式專區\TradingSysteam\lib\site-packages\sqlalchemy\engine\base.py", line 1572, in _execute_clauseelement
    ret = self._execute_context(
  File "C:\Users\user\Desktop\程式專區\TradingSysteam\lib\site-packages\sqlalchemy\engine\base.py", line 1943, in _execute_context
    self._handle_dbapi_exception(
  File "C:\Users\user\Desktop\程式專區\TradingSysteam\lib\site-packages\sqlalchemy\engine\base.py", line 2124, in _handle_dbapi_exception
    util.raise_(
  File "C:\Users\user\Desktop\程式專區\TradingSysteam\lib\site-packages\sqlalchemy\util\compat.py", line 210, in raise_
    raise exception
  File "C:\Users\user\Desktop\程式專區\TradingSysteam\lib\site-packages\sqlalchemy\engine\base.py", line 1900, in _execute_context
    self.dialect.do_execute(
  File "C:\Users\user\Desktop\程式專區\TradingSysteam\lib\site-packages\sqlalchemy\engine\default.py", line 736, in do_execute
    cursor.execute(statement, parameters)
  File "C:\Users\user\Desktop\程式專區\TradingSysteam\lib\site-packages\pymysql\cursors.py", line 158, in execute
    result = self._query(query)
  File "C:\Users\user\Desktop\程式專區\TradingSysteam\lib\site-packages\pymysql\cursors.py", line 325, in _query
    conn.query(q)
  File "C:\Users\user\Desktop\程式專區\TradingSysteam\lib\site-packages\pymysql\connections.py", line 549, in query
    self._affected_rows = self._read_query_result(unbuffered=unbuffered)
  File "C:\Users\user\Desktop\程式專區\TradingSysteam\lib\site-packages\pymysql\connections.py", line 779, in _read_query_result
    result.read()
  File "C:\Users\user\Desktop\程式專區\TradingSysteam\lib\site-packages\pymysql\connections.py", line 1157, in read
    first_packet = self.connection._read_packet()
  File "C:\Users\user\Desktop\程式專區\TradingSysteam\lib\site-packages\pymysql\connections.py", line 729, in _read_packet
    packet.raise_for_error()
  File "C:\Users\user\Desktop\程式專區\TradingSysteam\lib\site-packages\pymysql\protocol.py", line 221, in raise_for_error
    err.raise_mysql_exception(self._data)
  File "C:\Users\user\Desktop\程式專區\TradingSysteam\lib\site-packages\pymysql\err.py", line 143, in raise_mysql_exception
    raise errorclass(errno, errval)
sqlalchemy.exc.OperationalError: (pymysql.err.OperationalError) (3730, "Cannot drop table 'auth_group' referenced by a foreign key constraint 'auth_user_groups_group_id_97559544_fk_auth_group_id' on table 'auth_user_groups'.")
[SQL: drop table `auth_group`]
(Background on this error at: https://sqlalche.me/e/14/e3q8)

2023-10-29 12:57 ERROR Traceback (most recent call last):
  File "C:\Users\user\Desktop\程式專區\TradingSysteam\lib\site-packages\sqlalchemy\engine\base.py", line 1900, in _execute_context
    self.dialect.do_execute(
  File "C:\Users\user\Desktop\程式專區\TradingSysteam\lib\site-packages\sqlalchemy\engine\default.py", line 736, in do_execute
    cursor.execute(statement, parameters)
  File "C:\Users\user\Desktop\程式專區\TradingSysteam\lib\site-packages\pymysql\cursors.py", line 158, in execute
    result = self._query(query)
  File "C:\Users\user\Desktop\程式專區\TradingSysteam\lib\site-packages\pymysql\cursors.py", line 325, in _query
    conn.query(q)
  File "C:\Users\user\Desktop\程式專區\TradingSysteam\lib\site-packages\pymysql\connections.py", line 549, in query
    self._affected_rows = self._read_query_result(unbuffered=unbuffered)
  File "C:\Users\user\Desktop\程式專區\TradingSysteam\lib\site-packages\pymysql\connections.py", line 779, in _read_query_result
    result.read()
  File "C:\Users\user\Desktop\程式專區\TradingSysteam\lib\site-packages\pymysql\connections.py", line 1157, in read
    first_packet = self.connection._read_packet()
  File "C:\Users\user\Desktop\程式專區\TradingSysteam\lib\site-packages\pymysql\connections.py", line 729, in _read_packet
    packet.raise_for_error()
  File "C:\Users\user\Desktop\程式專區\TradingSysteam\lib\site-packages\pymysql\protocol.py", line 221, in raise_for_error
    err.raise_mysql_exception(self._data)
  File "C:\Users\user\Desktop\程式專區\TradingSysteam\lib\site-packages\pymysql\err.py", line 143, in raise_mysql_exception
    raise errorclass(errno, errval)
pymysql.err.OperationalError: (3730, "Cannot drop table 'auth_group' referenced by a foreign key constraint 'auth_user_groups_group_id_97559544_fk_auth_group_id' on table 'auth_user_groups'.")

The above exception was the direct cause of the following exception:

Traceback (most recent call last):
  File "C:\Users\user\Desktop\程式專區\TradingSysteam\Crypto_trading\Database\SQL_operate.py", line 54, in change_db_data
    conn.execute(text(text_msg))
  File "C:\Users\user\Desktop\程式專區\TradingSysteam\lib\site-packages\sqlalchemy\engine\base.py", line 1380, in execute
    return meth(self, multiparams, params, _EMPTY_EXECUTION_OPTS)
  File "C:\Users\user\Desktop\程式專區\TradingSysteam\lib\site-packages\sqlalchemy\sql\elements.py", line 334, in _execute_on_connection
    return connection._execute_clauseelement(
  File "C:\Users\user\Desktop\程式專區\TradingSysteam\lib\site-packages\sqlalchemy\engine\base.py", line 1572, in _execute_clauseelement
    ret = self._execute_context(
  File "C:\Users\user\Desktop\程式專區\TradingSysteam\lib\site-packages\sqlalchemy\engine\base.py", line 1943, in _execute_context
    self._handle_dbapi_exception(
  File "C:\Users\user\Desktop\程式專區\TradingSysteam\lib\site-packages\sqlalchemy\engine\base.py", line 2124, in _handle_dbapi_exception
    util.raise_(
  File "C:\Users\user\Desktop\程式專區\TradingSysteam\lib\site-packages\sqlalchemy\util\compat.py", line 210, in raise_
    raise exception
  File "C:\Users\user\Desktop\程式專區\TradingSysteam\lib\site-packages\sqlalchemy\engine\base.py", line 1900, in _execute_context
    self.dialect.do_execute(
  File "C:\Users\user\Desktop\程式專區\TradingSysteam\lib\site-packages\sqlalchemy\engine\default.py", line 736, in do_execute
    cursor.execute(statement, parameters)
  File "C:\Users\user\Desktop\程式專區\TradingSysteam\lib\site-packages\pymysql\cursors.py", line 158, in execute
    result = self._query(query)
  File "C:\Users\user\Desktop\程式專區\TradingSysteam\lib\site-packages\pymysql\cursors.py", line 325, in _query
    conn.query(q)
  File "C:\Users\user\Desktop\程式專區\TradingSysteam\lib\site-packages\pymysql\connections.py", line 549, in query
    self._affected_rows = self._read_query_result(unbuffered=unbuffered)
  File "C:\Users\user\Desktop\程式專區\TradingSysteam\lib\site-packages\pymysql\connections.py", line 779, in _read_query_result
    result.read()
  File "C:\Users\user\Desktop\程式專區\TradingSysteam\lib\site-packages\pymysql\connections.py", line 1157, in read
    first_packet = self.connection._read_packet()
  File "C:\Users\user\Desktop\程式專區\TradingSysteam\lib\site-packages\pymysql\connections.py", line 729, in _read_packet
    packet.raise_for_error()
  File "C:\Users\user\Desktop\程式專區\TradingSysteam\lib\site-packages\pymysql\protocol.py", line 221, in raise_for_error
    err.raise_mysql_exception(self._data)
  File "C:\Users\user\Desktop\程式專區\TradingSysteam\lib\site-packages\pymysql\err.py", line 143, in raise_mysql_exception
    raise errorclass(errno, errval)
sqlalchemy.exc.OperationalError: (pymysql.err.OperationalError) (3730, "Cannot drop table 'auth_group' referenced by a foreign key constraint 'auth_user_groups_group_id_97559544_fk_auth_group_id' on table 'auth_user_groups'.")
[SQL: drop table `auth_group`]
(Background on this error at: https://sqlalche.me/e/14/e3q8)

