2023-10-16 08:31 ERROR Traceback (most recent call last):
  File "C:\Users\user\Desktop\程式專區\TradingSysteam\lib\site-packages\pandas\core\indexes\base.py", line 3652, in get_loc
    return self._engine.get_loc(casted_key)
  File "pandas\_libs\index.pyx", line 147, in pandas._libs.index.IndexEngine.get_loc
  File "pandas\_libs\index.pyx", line 176, in pandas._libs.index.IndexEngine.get_loc
  File "pandas\_libs\hashtable_class_helper.pxi", line 7080, in pandas._libs.hashtable.PyObjectHashTable.get_item
  File "pandas\_libs\hashtable_class_helper.pxi", line 7088, in pandas._libs.hashtable.PyObjectHashTable.get_item
KeyError: 'Datetime'

The above exception was the direct cause of the following exception:

Traceback (most recent call last):
  File "C:\Users\user\Desktop\程式專區\TradingSysteam\Crypto_trading\Trading_Systeam.py", line 378, in main
    pf = self.engine.Portfolio_start()
  File "C:\Users\user\Desktop\程式專區\TradingSysteam\Crypto_trading\DQN\lib\Backtest.py", line 338, in Portfolio_start
    pf = self.Trader.logic_order()
  File "C:\Users\user\Desktop\程式專區\TradingSysteam\Crypto_trading\DQN\lib\Backtest.py", line 197, in logic_order
    self.add_data()
  File "C:\Users\user\Desktop\程式專區\TradingSysteam\Crypto_trading\DQN\lib\Backtest.py", line 136, in add_data
    pf = Record_Orders(strategy, self.formal).getpf()
  File "C:\Users\user\Desktop\程式專區\TradingSysteam\Crypto_trading\DQN\lib\run_model.py", line 83, in __init__
    self.pf = Backtest.Backtest(
  File "C:\Users\user\Desktop\程式專區\TradingSysteam\Crypto_trading\DQN\lib\Backtest.py", line 43, in order_becktest
    datetime_list = self.Symbol_data['Datetime'].to_list()
  File "C:\Users\user\Desktop\程式專區\TradingSysteam\lib\site-packages\pandas\core\frame.py", line 3760, in __getitem__
    indexer = self.columns.get_loc(key)
  File "C:\Users\user\Desktop\程式專區\TradingSysteam\lib\site-packages\pandas\core\indexes\base.py", line 3654, in get_loc
    raise KeyError(key) from err
KeyError: 'Datetime'

2023-10-16 08:55 ERROR Traceback (most recent call last):
  File "C:\Users\user\Desktop\程式專區\TradingSysteam\Crypto_trading\Trading_Systeam.py", line 378, in main
    pf = self.engine.Portfolio_start()
  File "C:\Users\user\Desktop\程式專區\TradingSysteam\Crypto_trading\DQN\lib\Backtest.py", line 343, in Portfolio_start
    pf = self.Trader.logic_order()
  File "C:\Users\user\Desktop\程式專區\TradingSysteam\Crypto_trading\DQN\lib\Backtest.py", line 294, in logic_order
    Picture_maker(Order_Info)
  File "C:\Users\user\Desktop\程式專區\TradingSysteam\Crypto_trading\Plot_draw\Picture_Mode.py", line 19, in __init__
    self.get_Mdd_UI(self.pf.order.index.to_numpy(
  File "C:\Users\user\Desktop\程式專區\TradingSysteam\Crypto_trading\Plot_draw\Picture_Mode.py", line 74, in get_Mdd_UI
    x1_data = np.array([date.split(' ')[0] for date in x1_data])
  File "C:\Users\user\Desktop\程式專區\TradingSysteam\Crypto_trading\Plot_draw\Picture_Mode.py", line 74, in <listcomp>
    x1_data = np.array([date.split(' ')[0] for date in x1_data])
AttributeError: 'numpy.datetime64' object has no attribute 'split'

2023-10-16 09:36 ERROR Traceback (most recent call last):
  File "C:\Users\user\Desktop\程式專區\TradingSysteam\Crypto_trading\Trading_Systeam.py", line 381, in main
    pf = self.engine.Portfolio_start()
  File "C:\Users\user\Desktop\程式專區\TradingSysteam\Crypto_trading\DQN\lib\Backtest.py", line 343, in Portfolio_start
    pf = self.Trader.logic_order()
  File "C:\Users\user\Desktop\程式專區\TradingSysteam\Crypto_trading\DQN\lib\Backtest.py", line 294, in logic_order
    Picture_maker(Order_Info)
  File "C:\Users\user\Desktop\程式專區\TradingSysteam\Crypto_trading\Plot_draw\Picture_Mode.py", line 19, in __init__
    self.get_Mdd_UI(self.pf.order.index.to_numpy(
  File "C:\Users\user\Desktop\程式專區\TradingSysteam\Crypto_trading\Plot_draw\Picture_Mode.py", line 79, in get_Mdd_UI
    fig, (self.ax1, self.ax2, ax3) = plt.subplots(
  File "C:\Users\user\Desktop\程式專區\TradingSysteam\lib\site-packages\matplotlib\pyplot.py", line 1501, in subplots
    fig = figure(**fig_kw)
  File "C:\Users\user\Desktop\程式專區\TradingSysteam\lib\site-packages\matplotlib\_api\deprecation.py", line 454, in wrapper
    return func(*args, **kwargs)
  File "C:\Users\user\Desktop\程式專區\TradingSysteam\lib\site-packages\matplotlib\pyplot.py", line 840, in figure
    manager = new_figure_manager(
  File "C:\Users\user\Desktop\程式專區\TradingSysteam\lib\site-packages\matplotlib\pyplot.py", line 383, in new_figure_manager
    _warn_if_gui_out_of_main_thread()
  File "C:\Users\user\Desktop\程式專區\TradingSysteam\lib\site-packages\matplotlib\pyplot.py", line 361, in _warn_if_gui_out_of_main_thread
    if _get_required_interactive_framework(_get_backend_mod()):
  File "C:\Users\user\Desktop\程式專區\TradingSysteam\lib\site-packages\matplotlib\pyplot.py", line 208, in _get_backend_mod
    switch_backend(rcParams._get("backend"))
  File "C:\Users\user\Desktop\程式專區\TradingSysteam\lib\site-packages\matplotlib\pyplot.py", line 279, in switch_backend
    raise ImportError(
ImportError: Cannot load backend 'TkAgg' which requires the 'tk' interactive framework, as 'qt' is currently running

