2023-10-21 09:29 ERROR Traceback (most recent call last):
  File "C:\Users\user\Desktop\程式專區\TradingSysteam\lib\site-packages\sqlalchemy\engine\base.py", line 1900, in _execute_context
    self.dialect.do_execute(
  File "C:\Users\user\Desktop\程式專區\TradingSysteam\lib\site-packages\sqlalchemy\engine\default.py", line 736, in do_execute
    cursor.execute(statement, parameters)
  File "C:\Users\user\Desktop\程式專區\TradingSysteam\lib\site-packages\pymysql\cursors.py", line 158, in execute
    result = self._query(query)
  File "C:\Users\user\Desktop\程式專區\TradingSysteam\lib\site-packages\pymysql\cursors.py", line 325, in _query
    conn.query(q)
  File "C:\Users\user\Desktop\程式專區\TradingSysteam\lib\site-packages\pymysql\connections.py", line 549, in query
    self._affected_rows = self._read_query_result(unbuffered=unbuffered)
  File "C:\Users\user\Desktop\程式專區\TradingSysteam\lib\site-packages\pymysql\connections.py", line 779, in _read_query_result
    result.read()
  File "C:\Users\user\Desktop\程式專區\TradingSysteam\lib\site-packages\pymysql\connections.py", line 1157, in read
    first_packet = self.connection._read_packet()
  File "C:\Users\user\Desktop\程式專區\TradingSysteam\lib\site-packages\pymysql\connections.py", line 729, in _read_packet
    packet.raise_for_error()
  File "C:\Users\user\Desktop\程式專區\TradingSysteam\lib\site-packages\pymysql\protocol.py", line 221, in raise_for_error
    err.raise_mysql_exception(self._data)
  File "C:\Users\user\Desktop\程式專區\TradingSysteam\lib\site-packages\pymysql\err.py", line 143, in raise_mysql_exception
    raise errorclass(errno, errval)
pymysql.err.ProgrammingError: (1146, "Table 'crypto_data.bsvusdt-f' doesn't exist")

The above exception was the direct cause of the following exception:

Traceback (most recent call last):
  File "c:\Users\user\Desktop\程式專區\TradingSysteam\Crypto_trading\Database\SQL_operate.py", line 80, in read_Dateframe
    return pd.read_sql(text_msg, con=conn)
  File "C:\Users\user\Desktop\程式專區\TradingSysteam\lib\site-packages\pandas\io\sql.py", line 661, in read_sql
    return pandas_sql.read_query(
  File "C:\Users\user\Desktop\程式專區\TradingSysteam\lib\site-packages\pandas\io\sql.py", line 1736, in read_query
    result = self.execute(sql, params)
  File "C:\Users\user\Desktop\程式專區\TradingSysteam\lib\site-packages\pandas\io\sql.py", line 1560, in execute
    return self.con.exec_driver_sql(sql, *args)
  File "C:\Users\user\Desktop\程式專區\TradingSysteam\lib\site-packages\sqlalchemy\engine\base.py", line 1760, in exec_driver_sql
    return self._exec_driver_sql(
  File "C:\Users\user\Desktop\程式專區\TradingSysteam\lib\site-packages\sqlalchemy\engine\base.py", line 1669, in _exec_driver_sql
    ret = self._execute_context(
  File "C:\Users\user\Desktop\程式專區\TradingSysteam\lib\site-packages\sqlalchemy\engine\base.py", line 1943, in _execute_context
    self._handle_dbapi_exception(
  File "C:\Users\user\Desktop\程式專區\TradingSysteam\lib\site-packages\sqlalchemy\engine\base.py", line 2124, in _handle_dbapi_exception
    util.raise_(
  File "C:\Users\user\Desktop\程式專區\TradingSysteam\lib\site-packages\sqlalchemy\util\compat.py", line 210, in raise_
    raise exception
  File "C:\Users\user\Desktop\程式專區\TradingSysteam\lib\site-packages\sqlalchemy\engine\base.py", line 1900, in _execute_context
    self.dialect.do_execute(
  File "C:\Users\user\Desktop\程式專區\TradingSysteam\lib\site-packages\sqlalchemy\engine\default.py", line 736, in do_execute
    cursor.execute(statement, parameters)
  File "C:\Users\user\Desktop\程式專區\TradingSysteam\lib\site-packages\pymysql\cursors.py", line 158, in execute
    result = self._query(query)
  File "C:\Users\user\Desktop\程式專區\TradingSysteam\lib\site-packages\pymysql\cursors.py", line 325, in _query
    conn.query(q)
  File "C:\Users\user\Desktop\程式專區\TradingSysteam\lib\site-packages\pymysql\connections.py", line 549, in query
    self._affected_rows = self._read_query_result(unbuffered=unbuffered)
  File "C:\Users\user\Desktop\程式專區\TradingSysteam\lib\site-packages\pymysql\connections.py", line 779, in _read_query_result
    result.read()
  File "C:\Users\user\Desktop\程式專區\TradingSysteam\lib\site-packages\pymysql\connections.py", line 1157, in read
    first_packet = self.connection._read_packet()
  File "C:\Users\user\Desktop\程式專區\TradingSysteam\lib\site-packages\pymysql\connections.py", line 729, in _read_packet
    packet.raise_for_error()
  File "C:\Users\user\Desktop\程式專區\TradingSysteam\lib\site-packages\pymysql\protocol.py", line 221, in raise_for_error
    err.raise_mysql_exception(self._data)
  File "C:\Users\user\Desktop\程式專區\TradingSysteam\lib\site-packages\pymysql\err.py", line 143, in raise_mysql_exception
    raise errorclass(errno, errval)
sqlalchemy.exc.ProgrammingError: (pymysql.err.ProgrammingError) (1146, "Table 'crypto_data.bsvusdt-f' doesn't exist")
[SQL: select Datetime, Open, High, Low, Close, Volume from `bsvusdt-f`;]
(Background on this error at: https://sqlalche.me/e/14/f405)

